2025-03-08 16:17:02,909 INFO    MainThread:1173 [wandb_setup.py:_flush():67] Current SDK version is 0.19.8
2025-03-08 16:17:02,910 INFO    MainThread:1173 [wandb_setup.py:_flush():67] Configure stats pid to 1173
2025-03-08 16:17:02,910 INFO    MainThread:1173 [wandb_setup.py:_flush():67] Loading settings from /root/.config/wandb/settings
2025-03-08 16:17:02,911 INFO    MainThread:1173 [wandb_setup.py:_flush():67] Loading settings from /autodl-fs/data/MAML-test/wandb/settings
2025-03-08 16:17:02,911 INFO    MainThread:1173 [wandb_setup.py:_flush():67] Loading settings from environment variables
2025-03-08 16:17:02,911 INFO    MainThread:1173 [wandb_init.py:setup_run_log_directory():647] Logging user logs to /autodl-fs/data/MAML-test/wandb/offline-run-20250308_161702-wd7gbi7x/logs/debug.log
2025-03-08 16:17:02,912 INFO    MainThread:1173 [wandb_init.py:setup_run_log_directory():648] Logging internal logs to /autodl-fs/data/MAML-test/wandb/offline-run-20250308_161702-wd7gbi7x/logs/debug-internal.log
2025-03-08 16:17:02,912 INFO    MainThread:1173 [wandb_init.py:init():761] calling init triggers
2025-03-08 16:17:02,913 INFO    MainThread:1173 [wandb_init.py:init():766] wandb.init called with sweep_config: {}
config: {'benchmark_name': 'ML1', 'env_name': 'reach-v2', 'max_episode_steps': 500, 'num_epsiodes_of_validation': 4, 'num_lifetimes_for_validation': 120, 'seeding': False, 'seed': 1, 'device': 'auto', 'num_outer_loop_updates': 4000, 'num_inner_loops_per_update': 30, 'num_adaptation_updates_in_inner_loop': 1, 'num_env_steps_per_adaptation_update': 2000, 'num_env_steps_for_estimating_maml_loss': 4000, 'num_lifetime_steps': 6000, 'maml_agent_lr': 0.0005, 'maml_agent_epsilon': 1e-05, 'maml_critic_lr': 0.0005, 'adaptation_lr': 0.07, 'adaptation_gamma': 0.995, 'rewards_target_mean_for_maml_agent': 0.1, 'maml_agent_gamma': 0.995, 'maml_TRPO': {'cg_damping': 0.01, 'max_kl': 0.001, 'cg_iters': 10, 'line_search_max_steps': 10, 'line_search_backtrack_ratio': 0.6}, '_wandb': {}}
2025-03-08 16:17:02,913 INFO    MainThread:1173 [wandb_init.py:init():784] starting backend
2025-03-08 16:17:02,913 INFO    MainThread:1173 [wandb_init.py:init():788] sending inform_init request
2025-03-08 16:17:02,934 INFO    MainThread:1173 [backend.py:_multiprocessing_setup():101] multiprocessing start_methods=fork,spawn,forkserver, using: spawn
2025-03-08 16:17:02,935 INFO    MainThread:1173 [wandb_init.py:init():798] backend started and connected
2025-03-08 16:17:02,943 INFO    MainThread:1173 [wandb_init.py:init():891] updated telemetry
2025-03-08 16:17:02,954 INFO    MainThread:1173 [wandb_init.py:init():915] communicating run to backend with 90.0 second timeout
2025-03-08 16:17:03,079 INFO    MainThread:1173 [wandb_init.py:init():990] starting run threads in backend
2025-03-08 16:17:03,252 INFO    MainThread:1173 [wandb_run.py:_console_start():2375] atexit reg
2025-03-08 16:17:03,252 INFO    MainThread:1173 [wandb_run.py:_redirect():2227] redirect: wrap_raw
2025-03-08 16:17:03,253 INFO    MainThread:1173 [wandb_run.py:_redirect():2292] Wrapping output streams.
2025-03-08 16:17:03,254 INFO    MainThread:1173 [wandb_run.py:_redirect():2315] Redirects installed.
2025-03-08 16:17:03,257 INFO    MainThread:1173 [wandb_init.py:init():1032] run started, returning control to user process
2025-03-08 16:18:12,173 INFO    MsgRouterThr:1173 [mailbox.py:close():129] Closing mailbox, abandoning 0 handles.
2025-03-08 16:18:12,200 ERROR   ray_print_logs:1173 [redirect.py:_on_write():661] error in stderr callback
Traceback (most recent call last):
  File "/root/miniconda3/envs/maml/lib/python3.10/site-packages/wandb/sdk/lib/redirect.py", line 659, in _on_write
    cb(written_data)
  File "/root/miniconda3/envs/maml/lib/python3.10/site-packages/wandb/sdk/wandb_run.py", line 2302, in <lambda>
    lambda data: self._console_raw_callback("stderr", data),
  File "/root/miniconda3/envs/maml/lib/python3.10/site-packages/wandb/sdk/wandb_run.py", line 401, in wrapper_fn
    return func(self, *args, **kwargs)
  File "/root/miniconda3/envs/maml/lib/python3.10/site-packages/wandb/sdk/wandb_run.py", line 1444, in _console_raw_callback
    self._backend.interface.publish_output_raw(name, data)
  File "/root/miniconda3/envs/maml/lib/python3.10/site-packages/wandb/sdk/interface/interface.py", line 761, in publish_output_raw
    self._publish_output_raw(o)
  File "/root/miniconda3/envs/maml/lib/python3.10/site-packages/wandb/sdk/interface/interface_shared.py", line 38, in _publish_output_raw
    self._publish(rec)
  File "/root/miniconda3/envs/maml/lib/python3.10/site-packages/wandb/sdk/interface/interface_sock.py", line 39, in _publish
    self._sock_client.send_record_publish(record)
  File "/root/miniconda3/envs/maml/lib/python3.10/site-packages/wandb/sdk/lib/sock_client.py", line 174, in send_record_publish
    self.send_server_request(server_req)
  File "/root/miniconda3/envs/maml/lib/python3.10/site-packages/wandb/sdk/lib/sock_client.py", line 154, in send_server_request
    self._send_message(msg)
  File "/root/miniconda3/envs/maml/lib/python3.10/site-packages/wandb/sdk/lib/sock_client.py", line 151, in _send_message
    self._sendall_with_error_handle(header + data)
  File "/root/miniconda3/envs/maml/lib/python3.10/site-packages/wandb/sdk/lib/sock_client.py", line 130, in _sendall_with_error_handle
    sent = self._sock.send(data)
BrokenPipeError: [Errno 32] Broken pipe
2025-03-08 16:18:12,304 ERROR   ray_print_logs:1173 [redirect.py:_on_write():661] error in stderr callback
Traceback (most recent call last):
  File "/root/miniconda3/envs/maml/lib/python3.10/site-packages/wandb/sdk/lib/redirect.py", line 659, in _on_write
    cb(written_data)
  File "/root/miniconda3/envs/maml/lib/python3.10/site-packages/wandb/sdk/wandb_run.py", line 2302, in <lambda>
    lambda data: self._console_raw_callback("stderr", data),
  File "/root/miniconda3/envs/maml/lib/python3.10/site-packages/wandb/sdk/wandb_run.py", line 401, in wrapper_fn
    return func(self, *args, **kwargs)
  File "/root/miniconda3/envs/maml/lib/python3.10/site-packages/wandb/sdk/wandb_run.py", line 1444, in _console_raw_callback
    self._backend.interface.publish_output_raw(name, data)
  File "/root/miniconda3/envs/maml/lib/python3.10/site-packages/wandb/sdk/interface/interface.py", line 761, in publish_output_raw
    self._publish_output_raw(o)
  File "/root/miniconda3/envs/maml/lib/python3.10/site-packages/wandb/sdk/interface/interface_shared.py", line 38, in _publish_output_raw
    self._publish(rec)
  File "/root/miniconda3/envs/maml/lib/python3.10/site-packages/wandb/sdk/interface/interface_sock.py", line 39, in _publish
    self._sock_client.send_record_publish(record)
  File "/root/miniconda3/envs/maml/lib/python3.10/site-packages/wandb/sdk/lib/sock_client.py", line 174, in send_record_publish
    self.send_server_request(server_req)
  File "/root/miniconda3/envs/maml/lib/python3.10/site-packages/wandb/sdk/lib/sock_client.py", line 154, in send_server_request
    self._send_message(msg)
  File "/root/miniconda3/envs/maml/lib/python3.10/site-packages/wandb/sdk/lib/sock_client.py", line 151, in _send_message
    self._sendall_with_error_handle(header + data)
  File "/root/miniconda3/envs/maml/lib/python3.10/site-packages/wandb/sdk/lib/sock_client.py", line 130, in _sendall_with_error_handle
    sent = self._sock.send(data)
BrokenPipeError: [Errno 32] Broken pipe
2025-03-08 16:18:12,305 ERROR   ray_print_logs:1173 [redirect.py:_on_write():661] error in stderr callback
Traceback (most recent call last):
  File "/root/miniconda3/envs/maml/lib/python3.10/site-packages/wandb/sdk/lib/redirect.py", line 659, in _on_write
    cb(written_data)
  File "/root/miniconda3/envs/maml/lib/python3.10/site-packages/wandb/sdk/wandb_run.py", line 2302, in <lambda>
    lambda data: self._console_raw_callback("stderr", data),
  File "/root/miniconda3/envs/maml/lib/python3.10/site-packages/wandb/sdk/wandb_run.py", line 401, in wrapper_fn
    return func(self, *args, **kwargs)
  File "/root/miniconda3/envs/maml/lib/python3.10/site-packages/wandb/sdk/wandb_run.py", line 1444, in _console_raw_callback
    self._backend.interface.publish_output_raw(name, data)
  File "/root/miniconda3/envs/maml/lib/python3.10/site-packages/wandb/sdk/interface/interface.py", line 761, in publish_output_raw
    self._publish_output_raw(o)
  File "/root/miniconda3/envs/maml/lib/python3.10/site-packages/wandb/sdk/interface/interface_shared.py", line 38, in _publish_output_raw
    self._publish(rec)
  File "/root/miniconda3/envs/maml/lib/python3.10/site-packages/wandb/sdk/interface/interface_sock.py", line 39, in _publish
    self._sock_client.send_record_publish(record)
  File "/root/miniconda3/envs/maml/lib/python3.10/site-packages/wandb/sdk/lib/sock_client.py", line 174, in send_record_publish
    self.send_server_request(server_req)
  File "/root/miniconda3/envs/maml/lib/python3.10/site-packages/wandb/sdk/lib/sock_client.py", line 154, in send_server_request
    self._send_message(msg)
  File "/root/miniconda3/envs/maml/lib/python3.10/site-packages/wandb/sdk/lib/sock_client.py", line 151, in _send_message
    self._sendall_with_error_handle(header + data)
  File "/root/miniconda3/envs/maml/lib/python3.10/site-packages/wandb/sdk/lib/sock_client.py", line 130, in _sendall_with_error_handle
    sent = self._sock.send(data)
BrokenPipeError: [Errno 32] Broken pipe
2025-03-08 16:18:12,409 ERROR   ray_print_logs:1173 [redirect.py:_on_write():661] error in stderr callback
Traceback (most recent call last):
  File "/root/miniconda3/envs/maml/lib/python3.10/site-packages/wandb/sdk/lib/redirect.py", line 659, in _on_write
    cb(written_data)
  File "/root/miniconda3/envs/maml/lib/python3.10/site-packages/wandb/sdk/wandb_run.py", line 2302, in <lambda>
    lambda data: self._console_raw_callback("stderr", data),
  File "/root/miniconda3/envs/maml/lib/python3.10/site-packages/wandb/sdk/wandb_run.py", line 401, in wrapper_fn
    return func(self, *args, **kwargs)
  File "/root/miniconda3/envs/maml/lib/python3.10/site-packages/wandb/sdk/wandb_run.py", line 1444, in _console_raw_callback
    self._backend.interface.publish_output_raw(name, data)
  File "/root/miniconda3/envs/maml/lib/python3.10/site-packages/wandb/sdk/interface/interface.py", line 761, in publish_output_raw
    self._publish_output_raw(o)
  File "/root/miniconda3/envs/maml/lib/python3.10/site-packages/wandb/sdk/interface/interface_shared.py", line 38, in _publish_output_raw
    self._publish(rec)
  File "/root/miniconda3/envs/maml/lib/python3.10/site-packages/wandb/sdk/interface/interface_sock.py", line 39, in _publish
    self._sock_client.send_record_publish(record)
  File "/root/miniconda3/envs/maml/lib/python3.10/site-packages/wandb/sdk/lib/sock_client.py", line 174, in send_record_publish
    self.send_server_request(server_req)
  File "/root/miniconda3/envs/maml/lib/python3.10/site-packages/wandb/sdk/lib/sock_client.py", line 154, in send_server_request
    self._send_message(msg)
  File "/root/miniconda3/envs/maml/lib/python3.10/site-packages/wandb/sdk/lib/sock_client.py", line 151, in _send_message
    self._sendall_with_error_handle(header + data)
  File "/root/miniconda3/envs/maml/lib/python3.10/site-packages/wandb/sdk/lib/sock_client.py", line 130, in _sendall_with_error_handle
    sent = self._sock.send(data)
BrokenPipeError: [Errno 32] Broken pipe
2025-03-08 16:18:12,410 ERROR   ray_print_logs:1173 [redirect.py:_on_write():661] error in stderr callback
Traceback (most recent call last):
  File "/root/miniconda3/envs/maml/lib/python3.10/site-packages/wandb/sdk/lib/redirect.py", line 659, in _on_write
    cb(written_data)
  File "/root/miniconda3/envs/maml/lib/python3.10/site-packages/wandb/sdk/wandb_run.py", line 2302, in <lambda>
    lambda data: self._console_raw_callback("stderr", data),
  File "/root/miniconda3/envs/maml/lib/python3.10/site-packages/wandb/sdk/wandb_run.py", line 401, in wrapper_fn
    return func(self, *args, **kwargs)
  File "/root/miniconda3/envs/maml/lib/python3.10/site-packages/wandb/sdk/wandb_run.py", line 1444, in _console_raw_callback
    self._backend.interface.publish_output_raw(name, data)
  File "/root/miniconda3/envs/maml/lib/python3.10/site-packages/wandb/sdk/interface/interface.py", line 761, in publish_output_raw
    self._publish_output_raw(o)
  File "/root/miniconda3/envs/maml/lib/python3.10/site-packages/wandb/sdk/interface/interface_shared.py", line 38, in _publish_output_raw
    self._publish(rec)
  File "/root/miniconda3/envs/maml/lib/python3.10/site-packages/wandb/sdk/interface/interface_sock.py", line 39, in _publish
    self._sock_client.send_record_publish(record)
  File "/root/miniconda3/envs/maml/lib/python3.10/site-packages/wandb/sdk/lib/sock_client.py", line 174, in send_record_publish
    self.send_server_request(server_req)
  File "/root/miniconda3/envs/maml/lib/python3.10/site-packages/wandb/sdk/lib/sock_client.py", line 154, in send_server_request
    self._send_message(msg)
  File "/root/miniconda3/envs/maml/lib/python3.10/site-packages/wandb/sdk/lib/sock_client.py", line 151, in _send_message
    self._sendall_with_error_handle(header + data)
  File "/root/miniconda3/envs/maml/lib/python3.10/site-packages/wandb/sdk/lib/sock_client.py", line 130, in _sendall_with_error_handle
    sent = self._sock.send(data)
BrokenPipeError: [Errno 32] Broken pipe
2025-03-08 16:18:12,515 ERROR   ray_print_logs:1173 [redirect.py:_on_write():661] error in stderr callback
Traceback (most recent call last):
  File "/root/miniconda3/envs/maml/lib/python3.10/site-packages/wandb/sdk/lib/redirect.py", line 659, in _on_write
    cb(written_data)
  File "/root/miniconda3/envs/maml/lib/python3.10/site-packages/wandb/sdk/wandb_run.py", line 2302, in <lambda>
    lambda data: self._console_raw_callback("stderr", data),
  File "/root/miniconda3/envs/maml/lib/python3.10/site-packages/wandb/sdk/wandb_run.py", line 401, in wrapper_fn
    return func(self, *args, **kwargs)
  File "/root/miniconda3/envs/maml/lib/python3.10/site-packages/wandb/sdk/wandb_run.py", line 1444, in _console_raw_callback
    self._backend.interface.publish_output_raw(name, data)
  File "/root/miniconda3/envs/maml/lib/python3.10/site-packages/wandb/sdk/interface/interface.py", line 761, in publish_output_raw
    self._publish_output_raw(o)
  File "/root/miniconda3/envs/maml/lib/python3.10/site-packages/wandb/sdk/interface/interface_shared.py", line 38, in _publish_output_raw
    self._publish(rec)
  File "/root/miniconda3/envs/maml/lib/python3.10/site-packages/wandb/sdk/interface/interface_sock.py", line 39, in _publish
    self._sock_client.send_record_publish(record)
  File "/root/miniconda3/envs/maml/lib/python3.10/site-packages/wandb/sdk/lib/sock_client.py", line 174, in send_record_publish
    self.send_server_request(server_req)
  File "/root/miniconda3/envs/maml/lib/python3.10/site-packages/wandb/sdk/lib/sock_client.py", line 154, in send_server_request
    self._send_message(msg)
  File "/root/miniconda3/envs/maml/lib/python3.10/site-packages/wandb/sdk/lib/sock_client.py", line 151, in _send_message
    self._sendall_with_error_handle(header + data)
  File "/root/miniconda3/envs/maml/lib/python3.10/site-packages/wandb/sdk/lib/sock_client.py", line 130, in _sendall_with_error_handle
    sent = self._sock.send(data)
BrokenPipeError: [Errno 32] Broken pipe
2025-03-08 16:18:12,516 ERROR   ray_print_logs:1173 [redirect.py:_on_write():661] error in stderr callback
Traceback (most recent call last):
  File "/root/miniconda3/envs/maml/lib/python3.10/site-packages/wandb/sdk/lib/redirect.py", line 659, in _on_write
    cb(written_data)
  File "/root/miniconda3/envs/maml/lib/python3.10/site-packages/wandb/sdk/wandb_run.py", line 2302, in <lambda>
    lambda data: self._console_raw_callback("stderr", data),
  File "/root/miniconda3/envs/maml/lib/python3.10/site-packages/wandb/sdk/wandb_run.py", line 401, in wrapper_fn
    return func(self, *args, **kwargs)
  File "/root/miniconda3/envs/maml/lib/python3.10/site-packages/wandb/sdk/wandb_run.py", line 1444, in _console_raw_callback
    self._backend.interface.publish_output_raw(name, data)
  File "/root/miniconda3/envs/maml/lib/python3.10/site-packages/wandb/sdk/interface/interface.py", line 761, in publish_output_raw
    self._publish_output_raw(o)
  File "/root/miniconda3/envs/maml/lib/python3.10/site-packages/wandb/sdk/interface/interface_shared.py", line 38, in _publish_output_raw
    self._publish(rec)
  File "/root/miniconda3/envs/maml/lib/python3.10/site-packages/wandb/sdk/interface/interface_sock.py", line 39, in _publish
    self._sock_client.send_record_publish(record)
  File "/root/miniconda3/envs/maml/lib/python3.10/site-packages/wandb/sdk/lib/sock_client.py", line 174, in send_record_publish
    self.send_server_request(server_req)
  File "/root/miniconda3/envs/maml/lib/python3.10/site-packages/wandb/sdk/lib/sock_client.py", line 154, in send_server_request
    self._send_message(msg)
  File "/root/miniconda3/envs/maml/lib/python3.10/site-packages/wandb/sdk/lib/sock_client.py", line 151, in _send_message
    self._sendall_with_error_handle(header + data)
  File "/root/miniconda3/envs/maml/lib/python3.10/site-packages/wandb/sdk/lib/sock_client.py", line 130, in _sendall_with_error_handle
    sent = self._sock.send(data)
BrokenPipeError: [Errno 32] Broken pipe
2025-03-08 16:18:12,620 ERROR   ray_print_logs:1173 [redirect.py:_on_write():661] error in stderr callback
Traceback (most recent call last):
  File "/root/miniconda3/envs/maml/lib/python3.10/site-packages/wandb/sdk/lib/redirect.py", line 659, in _on_write
    cb(written_data)
  File "/root/miniconda3/envs/maml/lib/python3.10/site-packages/wandb/sdk/wandb_run.py", line 2302, in <lambda>
    lambda data: self._console_raw_callback("stderr", data),
  File "/root/miniconda3/envs/maml/lib/python3.10/site-packages/wandb/sdk/wandb_run.py", line 401, in wrapper_fn
    return func(self, *args, **kwargs)
  File "/root/miniconda3/envs/maml/lib/python3.10/site-packages/wandb/sdk/wandb_run.py", line 1444, in _console_raw_callback
    self._backend.interface.publish_output_raw(name, data)
  File "/root/miniconda3/envs/maml/lib/python3.10/site-packages/wandb/sdk/interface/interface.py", line 761, in publish_output_raw
    self._publish_output_raw(o)
  File "/root/miniconda3/envs/maml/lib/python3.10/site-packages/wandb/sdk/interface/interface_shared.py", line 38, in _publish_output_raw
    self._publish(rec)
  File "/root/miniconda3/envs/maml/lib/python3.10/site-packages/wandb/sdk/interface/interface_sock.py", line 39, in _publish
    self._sock_client.send_record_publish(record)
  File "/root/miniconda3/envs/maml/lib/python3.10/site-packages/wandb/sdk/lib/sock_client.py", line 174, in send_record_publish
    self.send_server_request(server_req)
  File "/root/miniconda3/envs/maml/lib/python3.10/site-packages/wandb/sdk/lib/sock_client.py", line 154, in send_server_request
    self._send_message(msg)
  File "/root/miniconda3/envs/maml/lib/python3.10/site-packages/wandb/sdk/lib/sock_client.py", line 151, in _send_message
    self._sendall_with_error_handle(header + data)
  File "/root/miniconda3/envs/maml/lib/python3.10/site-packages/wandb/sdk/lib/sock_client.py", line 130, in _sendall_with_error_handle
    sent = self._sock.send(data)
BrokenPipeError: [Errno 32] Broken pipe
2025-03-08 16:18:12,621 ERROR   ray_print_logs:1173 [redirect.py:_on_write():661] error in stderr callback
Traceback (most recent call last):
  File "/root/miniconda3/envs/maml/lib/python3.10/site-packages/wandb/sdk/lib/redirect.py", line 659, in _on_write
    cb(written_data)
  File "/root/miniconda3/envs/maml/lib/python3.10/site-packages/wandb/sdk/wandb_run.py", line 2302, in <lambda>
    lambda data: self._console_raw_callback("stderr", data),
  File "/root/miniconda3/envs/maml/lib/python3.10/site-packages/wandb/sdk/wandb_run.py", line 401, in wrapper_fn
    return func(self, *args, **kwargs)
  File "/root/miniconda3/envs/maml/lib/python3.10/site-packages/wandb/sdk/wandb_run.py", line 1444, in _console_raw_callback
    self._backend.interface.publish_output_raw(name, data)
  File "/root/miniconda3/envs/maml/lib/python3.10/site-packages/wandb/sdk/interface/interface.py", line 761, in publish_output_raw
    self._publish_output_raw(o)
  File "/root/miniconda3/envs/maml/lib/python3.10/site-packages/wandb/sdk/interface/interface_shared.py", line 38, in _publish_output_raw
    self._publish(rec)
  File "/root/miniconda3/envs/maml/lib/python3.10/site-packages/wandb/sdk/interface/interface_sock.py", line 39, in _publish
    self._sock_client.send_record_publish(record)
  File "/root/miniconda3/envs/maml/lib/python3.10/site-packages/wandb/sdk/lib/sock_client.py", line 174, in send_record_publish
    self.send_server_request(server_req)
  File "/root/miniconda3/envs/maml/lib/python3.10/site-packages/wandb/sdk/lib/sock_client.py", line 154, in send_server_request
    self._send_message(msg)
  File "/root/miniconda3/envs/maml/lib/python3.10/site-packages/wandb/sdk/lib/sock_client.py", line 151, in _send_message
    self._sendall_with_error_handle(header + data)
  File "/root/miniconda3/envs/maml/lib/python3.10/site-packages/wandb/sdk/lib/sock_client.py", line 130, in _sendall_with_error_handle
    sent = self._sock.send(data)
BrokenPipeError: [Errno 32] Broken pipe
